[10/Sep/2017 15:27:04] INFO [restaurantes.views:21] 2017-09-10 15:27:04 - se ha consultado la pagina de inicio
[10/Sep/2017 15:27:35] ERROR [django.request:124] Internal Server Error: /restaurantes/
Traceback (most recent call last):
  File "/home/pablo/SSBW/lib/python3.5/site-packages/django/core/handlers/exception.py", line 39, in inner
    response = get_response(request)
  File "/home/pablo/SSBW/lib/python3.5/site-packages/django/core/handlers/base.py", line 187, in _get_response
    response = self.process_exception_by_middleware(e, request)
  File "/home/pablo/SSBW/lib/python3.5/site-packages/django/core/handlers/base.py", line 185, in _get_response
    response = wrapped_callback(request, *callback_args, **callback_kwargs)
  File "/home/pablo/SSBW/sitio_web/restaurantes/views.py", line 22, in index
    category_list = restaurants.objects.order_by('-name')[:5]
  File "/home/pablo/SSBW/lib/python3.5/site-packages/mongoengine/queryset/manager.py", line 37, in __get__
    queryset = queryset_class(owner, owner._get_collection())
  File "/home/pablo/SSBW/lib/python3.5/site-packages/mongoengine/document.py", line 205, in _get_collection
    cls.ensure_indexes()
  File "/home/pablo/SSBW/lib/python3.5/site-packages/mongoengine/document.py", line 835, in ensure_indexes
    collection.create_index(fields, background=background, **opts)
  File "/home/pablo/SSBW/lib/python3.5/site-packages/pymongo/collection.py", line 1529, in create_index
    self.__create_index(keys, kwargs)
  File "/home/pablo/SSBW/lib/python3.5/site-packages/pymongo/collection.py", line 1417, in __create_index
    with self._socket_for_writes() as sock_info:
  File "/usr/lib/python3.5/contextlib.py", line 59, in __enter__
    return next(self.gen)
  File "/home/pablo/SSBW/lib/python3.5/site-packages/pymongo/mongo_client.py", line 823, in _get_socket
    server = self._get_topology().select_server(selector)
  File "/home/pablo/SSBW/lib/python3.5/site-packages/pymongo/topology.py", line 214, in select_server
    address))
  File "/home/pablo/SSBW/lib/python3.5/site-packages/pymongo/topology.py", line 189, in select_servers
    self._error_message(selector))
pymongo.errors.ServerSelectionTimeoutError: 127.0.0.1:27017: [Errno 111] Connection refused
[10/Sep/2017 15:27:35] ERROR [django.server:131] "GET /restaurantes/ HTTP/1.1" 500 106137
[10/Sep/2017 15:27:42] INFO [restaurantes.views:21] 2017-09-10 15:27:42 - se ha consultado la pagina de inicio
[10/Sep/2017 15:27:45] INFO [restaurantes.views:49] 2017-09-10 15:27:45 - se ha consultado la pagina de restaurantes
[10/Sep/2017 15:30:16] INFO [restaurantes.views:21] 2017-09-10 15:30:16 - se ha consultado la pagina de inicio
[10/Sep/2017 15:30:21] INFO [restaurantes.views:49] 2017-09-10 15:30:21 - se ha consultado la pagina de restaurantes
[10/Sep/2017 15:30:24] INFO [restaurantes.views:64] 2017-09-10 15:30:24 - se ha consultado la pagina del resurante 41568346
[10/Sep/2017 15:30:33] INFO [restaurantes.views:64] 2017-09-10 15:30:33 - se ha consultado la pagina del resurante 41644596
[10/Sep/2017 15:30:44] INFO [restaurantes.views:92] 2017-09-10 15:30:44 - se ha consultado la pagina de add restaurante
[10/Sep/2017 15:31:16] INFO [restaurantes.views:92] 2017-09-10 15:31:16 - se ha consultado la pagina de add restaurante
[10/Sep/2017 15:31:16] ERROR [django.request:124] Internal Server Error: /restaurantes/add/
Traceback (most recent call last):
  File "/home/pablo/SSBW/lib/python3.5/site-packages/django/core/handlers/exception.py", line 39, in inner
    response = get_response(request)
  File "/home/pablo/SSBW/lib/python3.5/site-packages/django/core/handlers/base.py", line 187, in _get_response
    response = self.process_exception_by_middleware(e, request)
  File "/home/pablo/SSBW/lib/python3.5/site-packages/django/core/handlers/base.py", line 185, in _get_response
    response = wrapped_callback(request, *callback_args, **callback_kwargs)
  File "/home/pablo/SSBW/lib/python3.5/site-packages/django/contrib/auth/decorators.py", line 23, in _wrapped_view
    return view_func(request, *args, **kwargs)
  File "/home/pablo/SSBW/sitio_web/restaurantes/views.py", line 99, in add
    handle_uploaded_file(len([name for name in os.listdir('static/img/restaurants/') ]) + 1, request.FILES['photo'])
FileNotFoundError: [Errno 2] No such file or directory: 'static/img/restaurants/'
[10/Sep/2017 15:31:16] ERROR [django.server:131] "POST /restaurantes/add/ HTTP/1.1" 500 72280
